<?xml version="1.0"?>
<robot name="dpr4_back_wheel" xmlns:xacro="http://ros.org/wiki/xacro">
<xacro:macro name="back_wheel" params="parent name *joint_origin">
<joint name="${name}_link" type="continuous">
  <xacro:insert_block name="joint_origin" />
  <parent link="${parent}" />
  <child link="${name}_link" />
  <axis xyz="-1 0 0" />
</joint>
<link name="${name}_link">
  <inertial>
    <origin xyz="0 0 0" rpy="0 0 0" />
    <mass value="0.2926460297435" />
    <inertia ixx="0.0009700000000000" ixy="0.0000000000000000" ixz="0.0000000000000000" iyy="0.0005000000000000" iyz="0.0000000000000000" izz="0.0005000000000000" />
  </inertial>
  <visual>
    <origin xyz="0 0 0" rpy="0 0 0" />
    <geometry>
      <mesh filename="package://dpr4_description/meshes/visual/back_wheel.stl" />
    </geometry>
  </visual>
  <collision>
    <origin xyz="0 0 0" rpy="0 0 0" />
    <geometry>
      <mesh filename="package://dpr4_description/meshes/collision/back_wheel.stl" />
    </geometry>
  </collision>
</link>
</xacro:macro>
</robot>
