<?xml version="1.0" encoding="UTF-8"?>
<robot name="OSCAR">
  <link name="base_link">
    <inertial>
      <origin xyz="0.145518889489149 0.188965806720538 0.47004606572847" rpy="0 0 0" />
      <mass value="31.6409583053883" />
      <inertia ixx="4.92495611014394" ixy="-0.010973204594922" ixz="-0.428318545144442" iyy="5.25345744381056" iyz="-0.0474528299634025" izz="1.58331518428402" />
    </inertial>
    <visual>
      <origin xyz="0 0 0" rpy="0 0 0" />
      <geometry>
        <mesh filename="package://oscar_description/meshes/base_link.STL" />
      </geometry>
      <material name="">
        <color rgba="0.752941176470588 0.752941176470588 0.752941176470588 1" />
      </material>
    </visual>
    <collision>
      <origin xyz="0 0 0" rpy="0 0 0" />
      <geometry>
        <mesh filename="package://oscar_description/meshes/base_link.STL" />
      </geometry>
    </collision>
  </link>
  <link name="aandrijfwiel_rechts">
    <inertial>
      <origin xyz="3.31193234313631E-05 8.88095680329215E-10 -9.92994401982639E-10" rpy="0 0 0" />
      <mass value="1.98850951394841" />
      <inertia ixx="0.0255265582167491" ixy="-4.8033735056954E-12" ixz="-9.09709213705383E-11" iyy="0.0130861364457636" iyz="1.35066389743611E-10" izz="0.0130861363409337" />
    </inertial>
    <visual>
      <origin xyz="0 0 0" rpy="0 0 0" />
      <geometry>
        <mesh filename="package://oscar_description/meshes/aandrijfwiel_rechts.STL" />
      </geometry>
      <material name="">
        <color rgba="0.294117647058824 0.294117647058824 0.294117647058824 1" />
      </material>
    </visual>
    <collision>
      <origin xyz="0 0 0" rpy="0 0 0" />
      <geometry>
        <mesh filename="package://oscar_description/meshes/aandrijfwiel_rechts.STL" />
      </geometry>
    </collision>
  </link>
  <joint name="motoras_rechts" type="continuous">
    <origin xyz="-0.0610091422953399 0.469275677790673 0.130661401040105" rpy="1.43463153506437 0.00686067939224516 1.57079137192323" />
    <parent link="base_link" />
    <child link="aandrijfwiel_rechts" />
    <axis xyz="1 0 0" />
  </joint>
  <link name="aandrijf_links">
    <inertial>
      <origin xyz="3.31193234313354E-05 8.88095819107093E-10 -9.92994367288169E-10" rpy="0 0 0" />
      <mass value="1.9885095139484" />
      <inertia ixx="0.0255265582167491" ixy="-4.80331827914723E-12" ixz="-9.0970967405932E-11" iyy="0.0130861364457636" iyz="1.35066389359839E-10" izz="0.0130861363409337" />
    </inertial>
    <visual>
      <origin xyz="0 0 0" rpy="0 0 0" />
      <geometry>
        <mesh filename="package://oscar_description/meshes/aandrijf_links.STL" />
      </geometry>
      <material name="">
        <color rgba="0.294117647058824 0.294117647058824 0.294117647058824 1" />
      </material>
    </visual>
    <collision>
      <origin xyz="0 0 0" rpy="0 0 0" />
      <geometry>
        <mesh filename="package://oscar_description/meshes/aandrijf_links.STL" />
      </geometry>
    </collision>
  </link>
  <joint name="motoraslinks" type="continuous">
    <origin xyz="-0.0610119665057251 -0.100710907612253 0.134571957615908" rpy="0.856802140670808 0.00686067939224831 1.57079137192323" />
    <parent link="base_link" />
    <child link="aandrijf_links" />
    <axis xyz="1 0 0" />
  </joint>
  <link name="passief_links">
    <inertial>
      <origin xyz="0.02476354089088 0.0818790644900511 -3.79470760369927E-17" rpy="0 0 0" />
      <mass value="0.0275781208850642" />
      <inertia ixx="4.4978983418183E-05" ixy="1.24410071792927E-05" ixz="7.76557159064782E-21" iyy="2.08578618373715E-05" iyz="3.65282958503417E-21" izz="4.2101742518477E-05" />
    </inertial>
    <visual>
      <origin xyz="0 0 0" rpy="0 0 0" />
      <geometry>
        <mesh filename="package://oscar_description/meshes/passief_links.STL" />
      </geometry>
      <material name="">
        <color rgba="0.752941176470588 0.752941176470588 0.752941176470588 1" />
      </material>
    </visual>
    <collision>
      <origin xyz="0 0 0" rpy="0 0 0" />
      <geometry>
        <mesh filename="package://oscar_description/meshes/passief_links.STL" />
      </geometry>
    </collision>
  </link>
  <joint name="yrotatie_links_passief" type="continuous">
    <origin xyz="0.373806955642397 0.000686479005100441 0.045773429249947" rpy="1.56392069147652 0.0231730912705171 -0.000729862123761098" />
    <parent link="base_link" />
    <child link="passief_links" />
    <axis xyz="0 1 0" />
  </joint>
  <link name="passief_wiel_links">
    <inertial>
      <origin xyz="7.61764877046933E-06 -3.99925366434406E-08 -1.09284715166247E-08" rpy="0 0 0" />
      <mass value="0.2926460297435" />
      <inertia ixx="0.000978801719089636" ixy="-1.07010617094868E-11" ixz="1.98404806890517E-12" iyy="0.000502580747885339" iyz="6.49693007763158E-11" izz="0.000502580442560153" />
    </inertial>
    <visual>
      <origin xyz="0 0 0" rpy="0 0 0" />
      <geometry>
        <mesh filename="package://oscar_description/meshes/passief_wiel_links.STL" />
      </geometry>
      <material name="">
        <color rgba="0.294117647058824 0.294117647058824 0.294117647058824 1" />
      </material>
    </visual>
    <collision>
      <origin xyz="0 0 0" rpy="0 0 0" />
      <geometry>
        <mesh filename="package://oscar_description/meshes/passief_wiel_links.STL" />
      </geometry>
    </collision>
  </link>
  <joint name="wiel_links_passief_joint" type="fixed">
    <origin xyz="0.0515096362203469 0.00999999999999997 -0.000499999999997314" rpy="2.3869575088601 1.5707963267949 0" />
    <parent link="passief_links" />
    <child link="passief_wiel_links" />
    <axis xyz="1 0 0" />
  </joint>
  <link name="passief_rechts">
    <inertial>
      <origin xyz="0.02476354089088 0.0818790644900511 5.55111512312578E-17" rpy="0 0 0" />
      <mass value="0.0275781208850642" />
      <inertia ixx="4.49789834181832E-05" ixy="1.24410071792928E-05" ixz="1.8422966602781E-20" iyy="2.08578618373715E-05" iyz="-4.6719160996995E-20" izz="4.2101742518477E-05" />
    </inertial>
    <visual>
      <origin xyz="0 0 0" rpy="0 0 0" />
      <geometry>
        <mesh filename="package://oscar_description/meshes/passief_rechts.STL" />
      </geometry>
      <material name="">
        <color rgba="0.752941176470588 0.752941176470588 0.752941176470588 1" />
      </material>
    </visual>
    <collision>
      <origin xyz="0 0 0" rpy="0 0 0" />
      <geometry>
        <mesh filename="package://oscar_description/meshes/passief_rechts.STL" />
      </geometry>
    </collision>
  </link>
  <joint name="yrotatie_rechts_passief" type="continuous">
    <origin xyz="0.373819879962153 0.367171554283413 0.0432587956780883" rpy="1.56291079697297 0.0228492297244313 -0.0446138555479234" />
    <parent link="base_link" />
    <child link="passief_rechts" />
    <axis xyz="0 1 0" />
  </joint>
  <link name="passief_wiel_rechts">
    <inertial>
      <!-- <origin xyz="7.61571720858667E-06 -5.3143839329195E-10 -1.28055205328437E-09" rpy="0 0 0" /> -->
      <origin xyz="7.61571720858667E-06 -5.3143839329195E-10 0.000499999999915179" rpy="0 0 0" />
      <mass value="0.29264656535805" />
      <inertia ixx="0.000978801985309352" ixy="-4.80647404269377E-13" ixz="-3.64463892042982E-12" iyy="0.000502580759463227" iyz="8.11291527504846E-12" izz="0.000502580756909003" />
    </inertial>
    <visual>
      <origin xyz="0 0 0" rpy="0 0 0" />
      <geometry>
        <mesh filename="package://oscar_description/meshes/passief_wiel_rechts.STL" />
      </geometry>
      <material name="">
        <color rgba="0.294117647058824 0.294117647058824 0.294117647058824 1" />
      </material>
    </visual>
    <collision>
      <origin xyz="0 0 0" rpy="0 0 0" />
      <geometry>
        <mesh filename="package://oscar_description/meshes/passief_wiel_rechts.STL" />
      </geometry>
    </collision>
  </link>
  <joint name="passief_wiel_rechts_joint" type="continuous">
    <!-- <origin xyz="0.0515096362203565 0.00999999999999988 0.000499999999915179" rpy="2.9256005116916 1.57079630572147 -3.06618110194042" /> -->
    <origin xyz="0.0515096362203565 0.00999999999999988 0.000499999999915179" rpy="2.9256005116916 1.57079630572147 -3.06618110194042" />
    <parent link="passief_rechts" />
    <child link="passief_wiel_rechts" />
    <axis xyz="1 0 0" />
  </joint>
</robot>
