<robot
  name="dpr4_description">
  <link
    name="base_link">
    <inertial>
      <origin
        xyz="0 0.23146 0.14798"
        rpy="0 0 0" />
      <mass
        value="12.0" />
      <inertia
        ixx="0.36685543"
        ixy="-0.00104218"
        ixz="-0.00036965"
        iyy="0.13334723"
        iyz="0.13386521"
        izz="0.35413958" />
    </inertial>
    <visual>
      <origin
        xyz="0 0 0"
        rpy="0 0 0" />
      <geometry>
        <mesh
          filename="package://dpr4_description/meshes/base_link.stl" />
      </geometry>
      <material
        name="">
        <color
          rgba="0.752941176470588 0.752941176470588 0.752941176470588 1" />
      </material>
    </visual>
    <collision>
      <origin
        xyz="0 0 0"
        rpy="0 0 0" />
      <geometry>
        <mesh
          filename="package://dpr4_description/meshes/base_link.stl" />
      </geometry>
    </collision>
  </link>
  <link
    name="AandrijfwielLinks">
    <inertial>
      <origin
        xyz="0 0 0"
        rpy="0 0 0" />
      <mass
        value="1.98850951394841" />
      <inertia
        ixx="0.0254040000000000"
        ixy="0.0000000000000000"
        ixz="0.0000000000000000"
        iyy="0.0130220000000000"
        iyz="0.0000000000000000"
        izz="0.0130220000000000" />
    </inertial>
    <visual>
      <origin
        xyz="0 0 0"
        rpy="0 0 0" />
      <geometry>
        <mesh
          filename="package://dpr4_description/meshes/Aandrijfwiel.stl" />
      </geometry>
      <material
        name="">
        <color
          rgba="0.294117647058824 0.294117647058824 0.294117647058824 1" />
      </material>
    </visual>
    <collision>
      <origin
        xyz="0 0 0"
        rpy="0 0 0" />
      <geometry>
        <mesh
          filename="package://dpr4_description/meshes/Aandrijfwiel.stl" />
      </geometry>
    </collision>
  </link>
  <joint
    name="AandrijfwielJointLinks"
    type="continuous">
    <origin
      xyz="-0.272 0.084 0.145"
      rpy="0 0 0" />
    <parent
      link="base_link" />
    <child
      link="AandrijfwielLinks" />
    <axis
      xyz="-1 0 0" />
  </joint>
  <link
    name="AandrijfwielRechts">
   <inertial>
      <origin
        xyz="0 0 0"
        rpy="0 0 0" />
      <mass
        value="1.98850951394841" />
      <inertia
        ixx="0.0254040000000000"
        ixy="0.0000000000000000"
        ixz="0.0000000000000000"
        iyy="0.0130220000000000"
        iyz="0.0000000000000000"
        izz="0.0130220000000000" />
    </inertial>
    <visual>
      <origin
        xyz="0 0 0"
        rpy="0 0 0" />
      <geometry>
        <mesh
          filename="package://dpr4_description/meshes/Aandrijfwiel.stl" />
      </geometry>
      <material
        name="">
        <color
          rgba="0.294117647058824 0.294117647058824 0.294117647058824 1" />
      </material>
    </visual>
    <collision>
      <origin
        xyz="0 0 0"
        rpy="0 0 0" />
      <geometry>
        <mesh
          filename="package://dpr4_description/meshes/Aandrijfwiel.stl" />
      </geometry>
    </collision>
  </link>
  <joint
    name="AandrijfwielJointRechts"
    type="continuous">
    <origin
      xyz="0.272 0.084 0.145"
      rpy="0 0 0" />
    <parent
      link="base_link" />
    <child
      link="AandrijfwielRechts" />
    <axis
      xyz="-1 0 0" />
  </joint>
  <link
    name="PassiefLinkLinks">
    <inertial>
      <origin
        xyz="0 0 0"
        rpy="0 0 0" />
      <mass
        value="0.027578120885064" />
      <inertia
        ixx="0.0000770000000000"
        ixy="0.0000000000000000"
        ixz="0.0000000000000000"
        iyy="0.0000750000000000"
        iyz="-0.0000250000000000"
        izz="0.0000260000000000" />
    </inertial>
    <visual>
      <origin
        xyz="0 0 0"
        rpy="0 0 0" />
      <geometry>
        <mesh
          filename="package://dpr4_description/meshes/PassiefLink.stl" />
      </geometry>
      <material
        name="">
        <color
          rgba="0.752941176470588 0.752941176470588 0.752941176470588 1" />
      </material>
    </visual>
    <collision>
      <origin
        xyz="0 0 0"
        rpy="0 0 0" />
      <geometry>
        <mesh
          filename="package://dpr4_description/meshes/PassiefLink.stl" />
      </geometry>
    </collision>
  </link>
  <joint
    name="PassiefJointLinks"
    type="continuous">
    <origin
      xyz="-0.183 0.532 0.182"
      rpy="0 0 0" />
    <parent
      link="base_link" />
    <child
      link="PassiefLinkLinks" />
    <axis
      xyz="0 0 1" />
  </joint>
  <link
    name="ZwenkwielLinks">
    <inertial>
      <origin
        xyz="0 0 0"
        rpy="0 0 0" />
      <mass
        value="0.2926460297435" />
      <inertia
        ixx="0.0009700000000000"
        ixy="0.0000000000000000"
        ixz="0.0000000000000000"
        iyy="0.0005000000000000"
        iyz="0.0000000000000000"
        izz="0.0005000000000000" />
    </inertial>
    <visual>
      <origin
        xyz="0 0 0"
        rpy="0 0 0" />
      <geometry>
        <mesh
          filename="package://dpr4_description/meshes/Zwenkwiel.stl" />
      </geometry>
      <material
        name="">
        <color
          rgba="0.294117647058824 0.294117647058824 0.294117647058824 1" />
      </material>
    </visual>
    <collision>
      <origin
        xyz="0 0 0"
        rpy="0 0 0" />
      <geometry>
        <mesh
          filename="package://dpr4_description/meshes/Zwenkwiel.stl" />
      </geometry>
    </collision>
  </link>
  <joint
    name="ZwenkwielJointLinks"
    type="continuous">
    <origin
      xyz="0 0.04025 -0.105"
      rpy="0 0 0" />
    <parent
      link="PassiefLinkLinks" />
    <child
      link="ZwenkwielLinks" />
    <axis
      xyz="-1 0 0" />
  </joint>
  <link
    name="PassiefLinkRechts">
    <inertial>
      <origin
        xyz="0 0 0"
        rpy="0 0 0" />
      <mass
        value="0.0275781208850642" />
      <inertia
        ixx="0.0000770000000000"
        ixy="0.0000000000000000"
        ixz="0.0000000000000000"
        iyy="0.0000750000000000"
        iyz="-0.0000250000000000"
        izz="0.0000260000000000" />
    </inertial>
    <visual>
      <origin
        xyz="0 0 0"
        rpy="0 0 0" />
      <geometry>
        <mesh
          filename="package://dpr4_description/meshes/PassiefLink.stl" />
      </geometry>
      <material
        name="">
        <color
          rgba="0.752941176470588 0.752941176470588 0.752941176470588 1" />
      </material>
    </visual>
    <collision>
      <origin
        xyz="0 0 0"
        rpy="0 0 0" />
      <geometry>
        <mesh
          filename="package://dpr4_description/meshes/PassiefLink.stl" />
      </geometry>
    </collision>
  </link>
  <joint
    name="PassiefJointRechts"
    type="continuous">
    <origin
      xyz="0.183 0.532 0.182"
      rpy="0 0 0" />
    <parent
      link="base_link" />
    <child
      link="PassiefLinkRechts" />
    <axis
      xyz="0 0 1" />
  </joint>
  <link
    name="ZwenkwielRechts">
    <inertial>
      <origin
        xyz="0 0 0"
        rpy="0 0 0" />
      <mass
        value="0.29264656535805" />
      <inertia
        ixx="0.0009700000000000"
        ixy="0.0000000000000000"
        ixz="0.0000000000000000"
        iyy="0.0005000000000000"
        iyz="0.0000000000000000"
        izz="0.0005000000000000" />
    </inertial>
    <visual>
      <origin
        xyz="0 0 0"
        rpy="0 0 0" />
      <geometry>
        <mesh
          filename="package://dpr4_description/meshes/Zwenkwiel.stl" />
      </geometry>
      <material
        name="">
        <color
          rgba="0.294117647058824 0.294117647058824 0.294117647058824 1" />
      </material>
    </visual>
    <collision>
      <origin
        xyz="0 0 0"
        rpy="0 0 0" />
      <geometry>
        <mesh
          filename="package://dpr4_description/meshes/Zwenkwiel.stl" />
      </geometry>
    </collision>
  </link>
  <joint
    name="ZwenkwielJointRechts"
    type="continuous">
    <origin
      xyz="0 0.04025 -0.105"
      rpy="0 0 0" />
    <parent
      link="PassiefLinkRechts" />
    <child
      link="ZwenkwielRechts" />
    <axis
      xyz="-1 0 0" />
  </joint>
</robot>
