<robot
  name="dpr4_description">
  <link
    name="base_link">
    <inertial>
      <origin
        xyz="0 0.23146 0.14798"
        rpy="0 0 0" />
      <mass
        value="12.0" />
      <inertia
        ixx="1.30161345"
        ixy="-0.00690756"
        ixz="-0.00131153"
        iyy="0.47311975"
        iyz="0.47495754"
        izz="1.25649724" />
    </inertial>
    <visual>
      <origin
        xyz="0 0 0"
        rpy="0 0 0" />
      <geometry>
        <mesh
          filename="package://dpr4_description/meshes/base_link.stl" />
      </geometry>
      <material
        name="">
        <color
          rgba="0.752941176470588 0.752941176470588 0.752941176470588 1" />
      </material>
    </visual>
    <collision>
      <origin
        xyz="0 0 0"
        rpy="0 0 0" />
      <geometry>
        <mesh
          filename="package://dpr4_description/meshes/base_link.stl" />
      </geometry>
    </collision>
  </link>
  <link
    name="front_wheel_left">
    <inertial>
      <origin
        xyz="0 0 0"
        rpy="0 0 0" />
      <mass
        value="1.98850951394841" />
      <inertia
        ixx="0.0254040000000000"
        ixy="0.0000000000000000"
        ixz="0.0000000000000000"
        iyy="0.0130220000000000"
        iyz="0.0000000000000000"
        izz="0.0130220000000000" />
    </inertial>
    <visual>
      <origin
        xyz="0 0 0"
        rpy="0 0 0" />
      <geometry>
        <mesh
          filename="package://dpr4_description/meshes/front_wheel.stl" />
      </geometry>
      <material
        name="">
        <color
          rgba="0.294117647058824 0.294117647058824 0.294117647058824 1" />
      </material>
    </visual>
    <collision>
      <origin
        xyz="0 0 0"
        rpy="0 0 0" />
      <geometry>
        <mesh
          filename="package://dpr4_description/meshes/front_wheel.stl" />
      </geometry>
    </collision>
  </link>
  <joint
    name="front_wheel_left_joint"
    type="continuous">
    <origin
      xyz="-0.272 0.084 0.145"
      rpy="0 0 0" />
    <parent
      link="base_link" />
    <child
      link="front_wheel_left" />
    <axis
      xyz="-1 0 0" />
  </joint>
  <link
    name="front_wheel_right">
   <inertial>
      <origin
        xyz="0 0 0"
        rpy="0 0 0" />
      <mass
        value="1.98850951394841" />
      <inertia
        ixx="0.0254040000000000"
        ixy="0.0000000000000000"
        ixz="0.0000000000000000"
        iyy="0.0130220000000000"
        iyz="0.0000000000000000"
        izz="0.0130220000000000" />
    </inertial>
    <visual>
      <origin
        xyz="0 0 0"
        rpy="0 0 0" />
      <geometry>
        <mesh
          filename="package://dpr4_description/meshes/front_wheel.stl" />
      </geometry>
      <material
        name="">
        <color
          rgba="0.294117647058824 0.294117647058824 0.294117647058824 1" />
      </material>
    </visual>
    <collision>
      <origin
        xyz="0 0 0"
        rpy="0 0 0" />
      <geometry>
        <mesh
          filename="package://dpr4_description/meshes/front_wheel.stl" />
      </geometry>
    </collision>
  </link>
  <joint
    name="front_wheel_right_joint"
    type="continuous">
    <origin
      xyz="0.272 0.084 0.145"
      rpy="0 0 0" />
    <parent
      link="base_link" />
    <child
      link="front_wheel_right" />
    <axis
      xyz="-1 0 0" />
  </joint>
  <link
    name="yoke_left">
    <inertial>
      <origin
        xyz="0 0.01701 -0.04258"
        rpy="0 0 0" />
      <mass
        value="0.027578120885064" />
      <inertia
        ixx="0.00004501"
        ixy="0.0000000000000000"
        ixz="0.0000000000000000"
        iyy="0.00004508"
        iyz="-0.00001339"
        izz="0.00002122" />
    </inertial>
    <visual>
      <origin
        xyz="0 0 0"
        rpy="0 0 0" />
      <geometry>
        <mesh
          filename="package://dpr4_description/meshes/yoke.stl" />
      </geometry>
      <material
        name="">
        <color
          rgba="0.752941176470588 0.752941176470588 0.752941176470588 1" />
      </material>
    </visual>
    <collision>
      <origin
        xyz="0 0 0"
        rpy="0 0 0" />
      <geometry>
        <mesh
          filename="package://dpr4_description/meshes/yoke.stl" />
      </geometry>
    </collision>
  </link>
  <joint
    name="yoke_left_joint"
    type="continuous">
    <origin
      xyz="-0.183 0.532 0.182"
      rpy="0 0 0" />
    <parent
      link="base_link" />
    <child
      link="yoke_left" />
    <axis
      xyz="0 0 1" />
  </joint>
  <link
    name="back_wheel_left">
    <inertial>
      <origin
        xyz="0 0 0"
        rpy="0 0 0" />
      <mass
        value="0.2926460297435" />
      <inertia
        ixx="0.0009700000000000"
        ixy="0.0000000000000000"
        ixz="0.0000000000000000"
        iyy="0.0005000000000000"
        iyz="0.0000000000000000"
        izz="0.0005000000000000" />
    </inertial>
    <visual>
      <origin
        xyz="0 0 0"
        rpy="0 0 0" />
      <geometry>
        <mesh
          filename="package://dpr4_description/meshes/back_wheel.stl" />
      </geometry>
      <material
        name="">
        <color
          rgba="0.294117647058824 0.294117647058824 0.294117647058824 1" />
      </material>
    </visual>
    <collision>
      <origin
        xyz="0 0 0"
        rpy="0 0 0" />
      <geometry>
        <mesh
          filename="package://dpr4_description/meshes/back_wheel.stl" />
      </geometry>
    </collision>
  </link>
  <joint
    name="back_wheel_left_joint"
    type="continuous">
    <origin
      xyz="0 0.04025 -0.105"
      rpy="0 0 0" />
    <parent
      link="yoke_left" />
    <child
      link="back_wheel_left" />
    <axis
      xyz="-1 0 0" />
  </joint>
  <link
    name="yoke_right">
    <inertial>
      <origin
        xyz="0 0.01701 -0.04258"
        rpy="0 0 0" />
      <mass
        value="0.0275781208850642" />
      <inertia
        ixx="0.0000770000000000"
        ixy="0.0000000000000000"
        ixz="0.0000000000000000"
        iyy="0.0000750000000000"
        iyz="-0.0000250000000000"
        izz="0.0000260000000000" />
    </inertial>
    <visual>
      <origin
        xyz="0 0 0"
        rpy="0 0 0" />
      <geometry>
        <mesh
          filename="package://dpr4_description/meshes/yoke.stl" />
      </geometry>
      <material
        name="">
        <color
          rgba="0.752941176470588 0.752941176470588 0.752941176470588 1" />
      </material>
    </visual>
    <collision>
      <origin
        xyz="0 0 0"
        rpy="0 0 0" />
      <geometry>
        <mesh
          filename="package://dpr4_description/meshes/yoke.stl" />
      </geometry>
    </collision>
  </link>
  <joint
    name="yoke_right_joint"
    type="continuous">
    <origin
      xyz="0.183 0.532 0.182"
      rpy="0 0 0" />
    <parent
      link="base_link" />
    <child
      link="yoke_right" />
    <axis
      xyz="0 0 1" />
  </joint>
  <link
    name="back_wheel_right">
    <inertial>
      <origin
        xyz="0 0 0"
        rpy="0 0 0" />
      <mass
        value="0.29264656535805" />
      <inertia
        ixx="0.0009700000000000"
        ixy="0.0000000000000000"
        ixz="0.0000000000000000"
        iyy="0.0005000000000000"
        iyz="0.0000000000000000"
        izz="0.0005000000000000" />
    </inertial>
    <visual>
      <origin
        xyz="0 0 0"
        rpy="0 0 0" />
      <geometry>
        <mesh
          filename="package://dpr4_description/meshes/back_wheel.stl" />
      </geometry>
      <material
        name="">
        <color
          rgba="0.294117647058824 0.294117647058824 0.294117647058824 1" />
      </material>
    </visual>
    <collision>
      <origin
        xyz="0 0 0"
        rpy="0 0 0" />
      <geometry>
        <mesh
          filename="package://dpr4_description/meshes/back_wheel.stl" />
      </geometry>
    </collision>
  </link>
  <joint
    name="back_wheel_right_joint"
    type="continuous">
    <origin
      xyz="0 0.04025 -0.105"
      rpy="0 0 0" />
    <parent
      link="yoke_right" />
    <child
      link="back_wheel_right" />
    <axis
      xyz="-1 0 0" />
  </joint>
</robot>
